<?xml version="1.0" ?>
<!-- =================================================================================== -->
<!-- |    This document was autogenerated by xacro from simple_pedulum.xacro           | -->
<!-- |    EDITING THIS FILE BY HAND IS NOT RECOMMENDED                                 | -->
<!-- =================================================================================== -->
<robot name="simple_pedulum">
  <material name="silver">
    <color rgba="0.700 0.700 0.700 1.000"/>
  </material>
  <transmission name="Ball2_tran">
    <type>transmission_interface/SimpleTransmission</type>
    <joint name="Ball2">
      <hardwareInterface>hardware_interface/EffortJointInterface</hardwareInterface>
    </joint>
    <actuator name="Ball2_actr">
      <hardwareInterface>hardware_interface/EffortJointInterface</hardwareInterface>
      <mechanicalReduction>1</mechanicalReduction>
    </actuator>
  </transmission>
  <gazebo>
    <plugin filename="libgazebo_ros_control.so" name="control"/>
  </gazebo>
  <gazebo reference="base_link">
    <material>Gazebo/Silver</material>
    <mu1>0.2</mu1>
    <mu2>0.2</mu2>
    <selfCollide>true</selfCollide>
    <gravity>true</gravity>
  </gazebo>
  <gazebo reference="pendulum_1">
    <material>Gazebo/Silver</material>
    <mu1>0.2</mu1>
    <mu2>0.2</mu2>
    <selfCollide>true</selfCollide>
  </gazebo>
  <link name="base_link">
    <inertial>
      <origin rpy="0 0 0" xyz="0.012500000038143316 0.045846826121013436 -0.024183593613065192"/>
      <mass value="0.9254518780839054"/>
      <inertia ixx="0.00585" ixy="-0.0" ixz="-0.0" iyy="0.004914" iyz="-0.000767" izz="0.001627"/>
    </inertial>
    <visual>
      <origin rpy="0 0 0" xyz="0 0 0"/>
      <geometry>
        <mesh filename="package://simple_pedulum_description/meshes/base_link.stl" scale="0.001 0.001 0.001"/>
      </geometry>
      <material name="silver"/>
    </visual>
    <collision>
      <origin rpy="0 0 0" xyz="0 0 0"/>
      <geometry>
        <mesh filename="package://simple_pedulum_description/meshes/base_link.stl" scale="0.001 0.001 0.001"/>
      </geometry>
    </collision>
  </link>
  <link name="pendulum_1">
    <inertial>
      <origin rpy="0 0 0" xyz="1.8632134030083236e-10 1.7881393241103716e-10 -0.13956521697300156"/>
      <mass value="0.10635272949009089"/>
      <inertia ixx="0.000173" ixy="-0.0" ixz="-0.0" iyy="0.000173" iyz="-0.0" izz="9e-06"/>
    </inertial>
    <visual>
      <origin rpy="0 0 0" xyz="-0.0125 -0.012 -0.175"/>
      <geometry>
        <mesh filename="package://simple_pedulum_description/meshes/pendulum_1.stl" scale="0.001 0.001 0.001"/>
      </geometry>
      <material name="silver"/>
    </visual>
    <collision>
      <origin rpy="0 0 0" xyz="-0.0125 -0.012 -0.175"/>
      <geometry>
        <mesh filename="package://simple_pedulum_description/meshes/pendulum_1.stl" scale="0.001 0.001 0.001"/>
      </geometry>
    </collision>
  </link>
  <joint name="Ball2" type="continuous">
    <origin rpy="0 0 0" xyz="0.0125 0.012 0.175"/>
    <parent link="base_link"/>
    <child link="pendulum_1"/>
  </joint>
</robot>

